<?xml version="1.0"?>
<robot name="myfirst">
  <link name="base_link">
    <visual>
      <geometry>
        <cylinder length="0.6" radius="0.2"/>
      </geometry>
     <origin xyz="0 0 0.3"/>
    </visual>
  </link>
 <link name="first_link">
  <visual>
   <geometry>
    <box size="1 .5 .2"/>
   </geometry>
   <origin xyz="0.5 0 0"/>
  </visual>
 </link>

 <link name="second_link">
  <visual>
   <geometry>
    <box size="1 .25 .2"/>
   </geometry>
   <origin xyz="0.5 0 0"/>
  </visual>
 </link>

 <link name="third_link">
  <visual>
   <geometry>
    <box size=".5 .1 .1"/>
   </geometry>
   <origin rpy="0 1.57075 0" xyz="0 0 0.25"/>
  </visual>
 </link>


<joint name="base_to_first_link" type="continuous">
    <parent link="base_link"/>
    <child link="first_link"/>
    <origin xyz="0 0 .7"/>
    <axis xyz="0 0 1" />
  </joint>

<joint name="first_to_second_link" type="continuous">
    <parent link="first_link"/>
    <child link="second_link"/>
    <origin xyz="1 0 0"/>
    <axis xyz="0 0 1" />
  </joint>

<joint name="second_to_third_link" type="prismatic">
    <parent link="second_link"/>
    <child link="third_link"/>
    <limit effort="1000.0" lower=".1" upper=".4" velocity="0.5"/>
    <origin xyz="1.05 0 0"/>
    <axis xyz="0 0 -1" />
  </joint>



</robot>

